[2025-10-13 02:20:52] [ERROR] [uvicorn.error:414] Exception in ASGI application
Traceback (most recent call last):
  File "/Users/arseniy/quadratic-equations/venv/lib/python3.13/site-packages/uvicorn/protocols/http/httptools_impl.py", line 409, in run_asgi
    result = await app(  # type: ignore[func-returns-value]
             ^^^^^^^^^^^^^^^^^^^^^^^^^^^^^^^^^^^^^^^^^^^^^^
        self.scope, self.receive, self.send
        ^^^^^^^^^^^^^^^^^^^^^^^^^^^^^^^^^^^
    )
    ^
  File "/Users/arseniy/quadratic-equations/venv/lib/python3.13/site-packages/uvicorn/middleware/proxy_headers.py", line 60, in __call__
    return await self.app(scope, receive, send)
           ^^^^^^^^^^^^^^^^^^^^^^^^^^^^^^^^^^^^
  File "/Users/arseniy/quadratic-equations/venv/lib/python3.13/site-packages/fastapi/applications.py", line 1133, in __call__
    await super().__call__(scope, receive, send)
  File "/Users/arseniy/quadratic-equations/venv/lib/python3.13/site-packages/starlette/applications.py", line 113, in __call__
    await self.middleware_stack(scope, receive, send)
  File "/Users/arseniy/quadratic-equations/venv/lib/python3.13/site-packages/starlette/middleware/errors.py", line 186, in __call__
    raise exc
  File "/Users/arseniy/quadratic-equations/venv/lib/python3.13/site-packages/starlette/middleware/errors.py", line 164, in __call__
    await self.app(scope, receive, _send)
  File "/Users/arseniy/quadratic-equations/venv/lib/python3.13/site-packages/starlette/middleware/exceptions.py", line 63, in __call__
    await wrap_app_handling_exceptions(self.app, conn)(scope, receive, send)
  File "/Users/arseniy/quadratic-equations/venv/lib/python3.13/site-packages/starlette/_exception_handler.py", line 53, in wrapped_app
    raise exc
  File "/Users/arseniy/quadratic-equations/venv/lib/python3.13/site-packages/starlette/_exception_handler.py", line 42, in wrapped_app
    await app(scope, receive, sender)
  File "/Users/arseniy/quadratic-equations/venv/lib/python3.13/site-packages/fastapi/middleware/asyncexitstack.py", line 18, in __call__
    await self.app(scope, receive, send)
  File "/Users/arseniy/quadratic-equations/venv/lib/python3.13/site-packages/starlette/routing.py", line 716, in __call__
    await self.middleware_stack(scope, receive, send)
  File "/Users/arseniy/quadratic-equations/venv/lib/python3.13/site-packages/starlette/routing.py", line 736, in app
    await route.handle(scope, receive, send)
  File "/Users/arseniy/quadratic-equations/venv/lib/python3.13/site-packages/starlette/routing.py", line 290, in handle
    await self.app(scope, receive, send)
  File "/Users/arseniy/quadratic-equations/venv/lib/python3.13/site-packages/fastapi/routing.py", line 123, in app
    await wrap_app_handling_exceptions(app, request)(scope, receive, send)
  File "/Users/arseniy/quadratic-equations/venv/lib/python3.13/site-packages/starlette/_exception_handler.py", line 53, in wrapped_app
    raise exc
  File "/Users/arseniy/quadratic-equations/venv/lib/python3.13/site-packages/starlette/_exception_handler.py", line 42, in wrapped_app
    await app(scope, receive, sender)
  File "/Users/arseniy/quadratic-equations/venv/lib/python3.13/site-packages/fastapi/routing.py", line 109, in app
    response = await f(request)
               ^^^^^^^^^^^^^^^^
  File "/Users/arseniy/quadratic-equations/venv/lib/python3.13/site-packages/fastapi/routing.py", line 389, in app
    raw_response = await run_endpoint_function(
                   ^^^^^^^^^^^^^^^^^^^^^^^^^^^^
    ...<3 lines>...
    )
    ^
  File "/Users/arseniy/quadratic-equations/venv/lib/python3.13/site-packages/fastapi/routing.py", line 290, in run_endpoint_function
    return await run_in_threadpool(dependant.call, **values)
           ^^^^^^^^^^^^^^^^^^^^^^^^^^^^^^^^^^^^^^^^^^^^^^^^^
  File "/Users/arseniy/quadratic-equations/venv/lib/python3.13/site-packages/starlette/concurrency.py", line 38, in run_in_threadpool
    return await anyio.to_thread.run_sync(func)
           ^^^^^^^^^^^^^^^^^^^^^^^^^^^^^^^^^^^^
  File "/Users/arseniy/quadratic-equations/venv/lib/python3.13/site-packages/anyio/to_thread.py", line 56, in run_sync
    return await get_async_backend().run_sync_in_worker_thread(
           ^^^^^^^^^^^^^^^^^^^^^^^^^^^^^^^^^^^^^^^^^^^^^^^^^^^^
        func, args, abandon_on_cancel=abandon_on_cancel, limiter=limiter
        ^^^^^^^^^^^^^^^^^^^^^^^^^^^^^^^^^^^^^^^^^^^^^^^^^^^^^^^^^^^^^^^^
    )
    ^
  File "/Users/arseniy/quadratic-equations/venv/lib/python3.13/site-packages/anyio/_backends/_asyncio.py", line 2485, in run_sync_in_worker_thread
    return await future
           ^^^^^^^^^^^^
  File "/Users/arseniy/quadratic-equations/venv/lib/python3.13/site-packages/anyio/_backends/_asyncio.py", line 976, in run
    result = context.run(func, *args)
  File "/Users/arseniy/quadratic-equations/api/v1/solvers.py", line 11, in answer_fast
    a,b,c = extract_coef(equasion)
            ~~~~~~~~~~~~^^^^^^^^^^
  File "/Users/arseniy/quadratic-equations/solving_simple_quadratic_equations.py", line 6, in extract_coef
    left,right = converts_strings(equasion)
                 ~~~~~~~~~~~~~~~~^^^^^^^^^^
  File "/Users/arseniy/quadratic-equations/solving_simple_quadratic_equations.py", line 38, in converts_strings
    left, right = equations.split("=")
    ^^^^^^^^^^^
ValueError: not enough values to unpack (expected 2, got 1)
